<?xml version="1.0" ?>
<sdf version="1.5">
	<world name="warehouse_rotate">
	
	<!-- A global light source -->
		<include>
			<uri>model://sun</uri>
		</include>
		<!-- A ground plane -->
		<include>
			<uri>model://ground_plane</uri>
		</include>
		<!--<include>
			<uri>model://kiva</uri>
		</include> -->
	<model name="basic_kiva">
		<static>false</static>
		<link name='chassis'>
           		<pose>0 0 .1 0 0 0</pose>
		        <collision name='collision'>
		         	<geometry>
		           		<box>
		              			<size>.4 .2 .1</size>
		            		</box>
		          	</geometry>
		        </collision>

		        <visual name='visual'>
		        	<geometry>
		            		<box>
		              			<size>.4 .2 .1</size>
		            		</box>
		          	</geometry>
		        </visual>
          	</link>
          	<link name="left_front_wheel">
        		<pose>0.15 0.13 0.05 0 1.5707 1.5707</pose>
			<collision name="collision">
  				<geometry>
    					<cylinder>
      						<radius>.05</radius>
      						<length>.05</length>
    					</cylinder>
  				</geometry>
			</collision>
			<visual name="visual">
  				<geometry>
    					<cylinder>
      						<radius>.05</radius>
      						<length>.05</length>
    					</cylinder>
  				</geometry>
			</visual>
      		</link>
      		<link name="left_back_wheel">
			<pose>-0.15 0.13 0.05 0 1.5707 1.5707</pose>
			<collision name="collision">
	  			<geometry>
	    				<cylinder>
		      				<radius>.05</radius>
		      				<length>.05</length>
	    				</cylinder>
	  			</geometry>
			</collision>
			<visual name="visual">
	  			<geometry>
	    				<cylinder>
		      				<radius>.05</radius>
		      				<length>.05</length>
	    				</cylinder>
	  			</geometry>
			</visual>
      		</link>
      		<link name="right_front_wheel">
			<pose>0.15 -0.13 0.05 0 1.5707 1.5707</pose>
			<collision name="collision">
	  			<geometry>
	    				<cylinder>
	      				<radius>.05</radius>
	      				<length>.05</length>
	    				</cylinder>
	  			</geometry>
			</collision>
			<visual name="visual">
	  			<geometry>
	    				<cylinder>
	      				<radius>.05</radius>
	      				<length>.05</length>
	    				</cylinder>
	  			</geometry>
			</visual>
      		</link>
      		<link name="right_back_wheel">
			<pose>-0.15 -0.13 0.05 0 1.5707 1.5707</pose>
			<collision name="collision">
	  			<geometry>
	    				<cylinder>
	      					<radius>.05</radius>
	      					<length>.05</length>
	   				</cylinder>
	  			</geometry>
			</collision>
			<visual name="visual">
          			<geometry>
            				<cylinder>
              					<radius>.05</radius>
              					<length>.05</length>
            				</cylinder>
          			</geometry>
       			</visual>
      		</link>
      		<link name="tower">
      			<visual name="tower">
        				<pose>0.00 0.00 0.15 0 0 0</pose>
        				<geometry>
          				<box>
            					<size>0.09 0.09 0.02</size>
          				</box>
        				</geometry>
      			</visual>
       			<collision name="tower">
        				<pose>0.00 0.00 0.16 0 0 0</pose>
        				<geometry>
          				<box>
            					<size>0.09 0.09 0.02</size>
          				</box>
        				</geometry>
      			</collision>
		</link>
		<link name="tower_plate">
      			<visual name="tower_plate">
        				<pose>0 0 0.165 0 0 0</pose>
        				<geometry>
          				<cylinder>
            					<length>0.01</length>
            					<radius>0.2</radius>
          				</cylinder>
        				</geometry>
      			</visual>
      			<collision name="tower_plate">
        				<pose>0 0 0.165 0 0 0</pose>
        				<geometry>
          				<cylinder>
            					<length>0.01</length>
            					<radius>0.2</radius>
          				</cylinder>
        				</geometry>
      			</collision>
    		</link>
      		<joint type="revolute" name="left_front_wheel_hinge">
        			<pose>0 0 -0.03 0 0 0</pose>
        			<child>left_front_wheel</child>
        			<parent>chassis</parent>
        			<axis>
          			<xyz>0 0 1</xyz>
       			</axis>
      		</joint>
		<joint type="revolute" name="left_back_wheel_hinge">
        			<pose>0 0 -0.03 0 0 0</pose>
        			<child>left_back_wheel</child>
        			<parent>chassis</parent>
        			<axis>
          			<xyz>0 0 1</xyz>
       			</axis>
      		</joint>
      		<joint type="revolute" name="right_front_wheel_hinge">
        			<pose>0 0 0.03 0 0 0</pose>
        			<child>right_front_wheel</child>
        			<parent>chassis</parent>
        			<axis>
          			<xyz>0 0 1</xyz>
        			</axis>
      		</joint>
      		<joint type="revolute" name="right_back_wheel_hinge">
        			<pose>0 0 0.03 0 0 0</pose>
        			<child>right_back_wheel</child>
        			<parent>chassis</parent>
        			<axis>
          			<xyz>0 0 1</xyz>
        			</axis>
      		</joint>
      		<joint type="fixed" name="tower_body">
        			<pose>0 0 0 0 0 0</pose>
        			<child>tower</child>
        			<parent>chassis</parent>
      		</joint>
      		<joint type="fixed" name="tower_head">
        			<pose>0 0 0 0 0 0</pose>
        			<child>tower_plate</child>
        			<parent>chassis</parent>
      		</joint>
		<!--<plugin name="kiva_rotate_center" filename="./kiva_plugins/build/libkiva_rotate_center.so">
			<direction>0</direction>
		</plugin>-->
		<plugin name="kiva_rotate_with_load" filename="./kiva_plugins/build/libkiva_rotate_with_load.so">
			<direction>1</direction>
		</plugin>
	</model>
	<model name="shelf">
			<link name='body'>
           		<pose>0 0 0.2 0 0 0</pose>
		        <collision name='collision'>
		         	<geometry>
		           		<box>
		              		<size>.8 .8 .05</size>
		            		</box>
		          	</geometry>
		        	</collision>

		        <visual name='visual'>
		        		<geometry>
		            		<box>
		              		<size>.8 .8 .05</size>
		            		</box>
		          	</geometry>
		        </visual>
			</link>
			<link name="leg_1">
            <pose>0.35 0.35 0.1 0 0 0</pose>
		        <collision name='collision'>
		         	<geometry>
		           		<box>
		              		<size>.1 .1 0.20</size>
		            		</box>
		          	</geometry>
		        	</collision>
		        <visual name='visual'>
		        		<geometry>
		            		<box>
		              		<size>.1 .1 0.20</size>
		            		</box>
		          	</geometry>
		        </visual>
			</link>
            <link name="leg_2">
            <pose>-0.35 0.35 0.1 0 0 0</pose>
		        <collision name='collision'>
		         	<geometry>
		           		<box>
		              		<size>.1 .1 0.20</size>
		            		</box>
		          	</geometry>
		        	</collision>

		        <visual name='visual'>
		        		<geometry>
		            		<box>
		              		<size>.1 .1 0.20</size>
		            		</box>
		          	</geometry>
		        </visual>
			</link>
            <link name="leg_3">
            <pose>0.35 -0.35 0.1 0 0 0</pose>
		        <collision name='collision'>
		         	<geometry>
		           		<box>
		              		<size>.1 .1 0.20</size>
		            		</box>
		          	</geometry>
		        	</collision>
		        <visual name='visual'>
		        		<geometry>
		            		<box>
		              		<size>.1 .1 0.20</size>
		            		</box>
		          	</geometry>
		        </visual>
			</link>
            <link name="leg_4">
            <pose>-0.35 -0.35 0.1 0 0 0</pose>
		        <collision name='collision'>
		         	<geometry>
		           		<box>
		              		<size>.1 .1 0.20</size>
		            		</box>
		          	</geometry>
		        	</collision>
		        <visual name='visual'>
		        		<geometry>
		            		<box>
		              		<size>.1 .1 0.20</size>
		            		</box>
		          	</geometry>
		        </visual>
			</link>
            <joint type="fixed" name="leg_1_joint">
        			<pose>0 0 0 0 0 0</pose>
        			<child>leg_1</child>
        			<parent>body</parent>
                </joint>
                <joint type="fixed" name="leg_2_joint">
        			<pose>0 0 0 0 0 0</pose>
        			<child>leg_2</child>
        			<parent>body</parent>
                </joint>
                <joint type="fixed" name="leg_3_joint">
        			<pose>0 0 0 0 0 0</pose>
        			<child>leg_3</child>
        			<parent>body</parent>
                </joint>
                <joint type="fixed" name="leg_4_joint">
        			<pose>0 0 0 0 0 0</pose>
        			<child>leg_4</child>
        			<parent>body</parent>
                </joint>
	</model>
	</world>
</sdf>
